<mujoco model="Aula_Video_1">
    <!--  Copyright © 2018, Roboti LLC

          This file is licensed under the MuJoCo Resource License (the "License").
          You may not use this file except in compliance with the License.
          You may obtain a copy of the License at

            https://www.roboti.us/resourcelicense.txt
    -->

    <include file="secne.xml"/>

    <option solver="CG" tolerance="1e-6"/> 

    <size nconmax="50" njmax="500" nstack="50000"/>
<!-- Dimensões de alocação -> numero máximo de contatos que o modelo pode fazer / numero jacobianos / numero da pilha -> problema maior em coisas mais flexiveis  -->
    <worldbody>
        <body name="link1_forreal" pos="0 0 0.5" quat="0.707 0 0 0.707">     <!-- Modelo que vamos trabalhar - quat="0.707 0 0 0.707" ou  euler="0 0 90" > rotaciona 90 graus em torno de Z--> 
          <!-- <geom type="capsule" fromto="-0.25 0 0 0.25 0.25 0" size="0.05" rgba="0.15 0.5 0.15 1"/>    -->
                    <!-- Colocar esse segundo 0.25 (o do meio) faz com que ele rotacione 45 graus - O Geom rotaciona mas o body não --> 
                    <!-- Geometria do modelo - capsule (PODE SER cylinder por exemplo) -> cilindro com uma esfera em cada ponta - fromto é um vertor que comeca em 0 0 0 e acaba em 0.25 0 0 -->
                    <!-- Colocar o -0.25 na frente faz com que ele se estenda 0,25 para tras -->
          <!-- <geom type="capsule" fromto="-0.25 0 0 0.25 -0.25 0" size="0.05" rgba="0.15 0.5 0.15 1"/>    -->
         
         
          <geom type="capsule" fromto="0 0 0 0.5 0.5 0" size="0.05" rgba="0.15 0.5 0.15 1"/>   
          <!-- Size é o raio -->
          <geom type="capsule" fromto="0 0 0 0.5 -0.5 0" size="0.05" rgba="0.15 0.5 0.15 1"/>   

          <!-- Assim, deixamos o body na origem -->

          <joint name="q1" type="hinge" pos="0 0 0" axis="0 0 1" limited="true" range="-120 120"/> 
          <!-- A junta está no ponto do body -->
          <!-- A junta é do tipo hinge (gira em torno de um eixo) - pos é a posição da junta (0 0 0) - axis é o eixo de rotação (0 0 1) - 
           limited=true significa que a junta tem limites - range é o intervalo de movimento da junta -->
            <!-- posso ter uma junta do tipo slide ewntre outras  -->
                 
 
              <body name="link2_batata" pos="0.25 0 0"> 
                    <!-- O body link2_batata está posicionado a 0.25 metros do link1_forreal -->
                  <geom type="capsule" fromto="0 0 0 0.25 0 0" size="0.035" rgba="0.5 0.15 0.15 1"/>
                  <joint name="q2" type="hinge" pos="0 0 0" axis="0 0 1" limited="true" range="-120 120"/>
                  <site name="ee" rgba="0 0 0 1" pos="0.25 0 0"/>
                  <site name="ee_visual" rgba="0 0 0 1" pos="0.25 0 0.035"/>
              </body>
      </body>
    </worldbody>

    <actuator>
    		<motor name="motor_1" joint="q1" gear="1"/>
    		<motor name="motor_2" joint="q2" gear="1"/>
    </actuator>
</mujoco>
